<?xml version="1.0" encoding="UTF-8"?>
<!-- Generated by org.testng.reporters.JUnitReportReporter -->
<testsuite skipped="0" hostname="Ajinkya" name="com.ajay.java.TestNG.AssertionInTestNG" tests="7" failures="3" timestamp="14 Dec 2019 07:34:46 GMT" time="0.024" errors="0">
  <testcase name="test6" time="0.000" classname="com.ajay.java.TestNG.AssertionInTestNG"/>
  <testcase name="test5" time="0.004" classname="com.ajay.java.TestNG.AssertionInTestNG"/>
  <testcase name="test4" time="0.000" classname="com.ajay.java.TestNG.AssertionInTestNG">
    <failure type="java.lang.AssertionError" message="not matching the expectd output.. expected [true] but found [false]">
      <![CDATA[java.lang.AssertionError: not matching the expectd output.. expected [true] but found [false]at org.testng.Assert.fail(Assert.java:96)at org.testng.Assert.failNotEquals(Assert.java:776)at org.testng.Assert.assertTrue(Assert.java:44)at com.ajay.java.TestNG.AssertionInTestNG.test4(AssertionInTestNG.java:32)at sun.reflect.NativeMethodAccessorImpl.invoke0(Native Method)at sun.reflect.NativeMethodAccessorImpl.invoke(Unknown Source)at sun.reflect.DelegatingMethodAccessorImpl.invoke(Unknown Source)at java.lang.reflect.Method.invoke(Unknown Source)at org.testng.internal.MethodInvocationHelper.invokeMethod(MethodInvocationHelper.java:124)at org.testng.internal.Invoker.invokeMethod(Invoker.java:571)at org.testng.internal.Invoker.invokeTestMethod(Invoker.java:707)at org.testng.internal.Invoker.invokeTestMethods(Invoker.java:979)at org.testng.internal.TestMethodWorker.invokeTestMethods(TestMethodWorker.java:125)at org.testng.internal.TestMethodWorker.run(TestMethodWorker.java:109)at org.testng.TestRunner.privateRun(TestRunner.java:648)at org.testng.TestRunner.run(TestRunner.java:505)at org.testng.SuiteRunner.runTest(SuiteRunner.java:455)at org.testng.SuiteRunner.runSequentially(SuiteRunner.java:450)at org.testng.SuiteRunner.privateRun(SuiteRunner.java:415)at org.testng.SuiteRunner.run(SuiteRunner.java:364)at org.testng.SuiteRunnerWorker.runSuite(SuiteRunnerWorker.java:52)at org.testng.SuiteRunnerWorker.run(SuiteRunnerWorker.java:84)at org.testng.TestNG.runSuitesSequentially(TestNG.java:1187)at org.testng.TestNG.runSuitesLocally(TestNG.java:1116)at org.testng.TestNG.runSuites(TestNG.java:1028)at org.testng.TestNG.run(TestNG.java:996)at org.testng.remote.AbstractRemoteTestNG.run(AbstractRemoteTestNG.java:114)at org.testng.remote.RemoteTestNG.initAndRun(RemoteTestNG.java:251)at org.testng.remote.RemoteTestNG.main(RemoteTestNG.java:77)]]>
    </failure>
  </testcase> <!-- test4 -->
  <testcase name="test2" time="0.000" classname="com.ajay.java.TestNG.AssertionInTestNG">
    <failure type="java.lang.AssertionError" message="expected [Test1] but found [Test]">
      <![CDATA[java.lang.AssertionError: expected [Test1] but found [Test]at org.testng.Assert.fail(Assert.java:96)at org.testng.Assert.failNotEquals(Assert.java:776)at org.testng.Assert.assertEqualsImpl(Assert.java:137)at org.testng.Assert.assertEquals(Assert.java:118)at org.testng.Assert.assertEquals(Assert.java:453)at org.testng.Assert.assertEquals(Assert.java:463)at com.ajay.java.TestNG.AssertionInTestNG.test2(AssertionInTestNG.java:21)at sun.reflect.NativeMethodAccessorImpl.invoke0(Native Method)at sun.reflect.NativeMethodAccessorImpl.invoke(Unknown Source)at sun.reflect.DelegatingMethodAccessorImpl.invoke(Unknown Source)at java.lang.reflect.Method.invoke(Unknown Source)at org.testng.internal.MethodInvocationHelper.invokeMethod(MethodInvocationHelper.java:124)at org.testng.internal.Invoker.invokeMethod(Invoker.java:571)at org.testng.internal.Invoker.invokeTestMethod(Invoker.java:707)at org.testng.internal.Invoker.invokeTestMethods(Invoker.java:979)at org.testng.internal.TestMethodWorker.invokeTestMethods(TestMethodWorker.java:125)at org.testng.internal.TestMethodWorker.run(TestMethodWorker.java:109)at org.testng.TestRunner.privateRun(TestRunner.java:648)at org.testng.TestRunner.run(TestRunner.java:505)at org.testng.SuiteRunner.runTest(SuiteRunner.java:455)at org.testng.SuiteRunner.runSequentially(SuiteRunner.java:450)at org.testng.SuiteRunner.privateRun(SuiteRunner.java:415)at org.testng.SuiteRunner.run(SuiteRunner.java:364)at org.testng.SuiteRunnerWorker.runSuite(SuiteRunnerWorker.java:52)at org.testng.SuiteRunnerWorker.run(SuiteRunnerWorker.java:84)at org.testng.TestNG.runSuitesSequentially(TestNG.java:1187)at org.testng.TestNG.runSuitesLocally(TestNG.java:1116)at org.testng.TestNG.runSuites(TestNG.java:1028)at org.testng.TestNG.run(TestNG.java:996)at org.testng.remote.AbstractRemoteTestNG.run(AbstractRemoteTestNG.java:114)at org.testng.remote.RemoteTestNG.initAndRun(RemoteTestNG.java:251)at org.testng.remote.RemoteTestNG.main(RemoteTestNG.java:77)]]>
    </failure>
  </testcase> <!-- test2 -->
  <testcase name="test1" time="0.000" classname="com.ajay.java.TestNG.AssertionInTestNG">
    <failure type="java.lang.AssertionError" message="expected [true] but found [false]">
      <![CDATA[java.lang.AssertionError: expected [true] but found [false]at org.testng.Assert.fail(Assert.java:96)at org.testng.Assert.failNotEquals(Assert.java:776)at org.testng.Assert.assertTrue(Assert.java:44)at org.testng.Assert.assertTrue(Assert.java:54)at com.ajay.java.TestNG.AssertionInTestNG.test1(AssertionInTestNG.java:16)at sun.reflect.NativeMethodAccessorImpl.invoke0(Native Method)at sun.reflect.NativeMethodAccessorImpl.invoke(Unknown Source)at sun.reflect.DelegatingMethodAccessorImpl.invoke(Unknown Source)at java.lang.reflect.Method.invoke(Unknown Source)at org.testng.internal.MethodInvocationHelper.invokeMethod(MethodInvocationHelper.java:124)at org.testng.internal.Invoker.invokeMethod(Invoker.java:571)at org.testng.internal.Invoker.invokeTestMethod(Invoker.java:707)at org.testng.internal.Invoker.invokeTestMethods(Invoker.java:979)at org.testng.internal.TestMethodWorker.invokeTestMethods(TestMethodWorker.java:125)at org.testng.internal.TestMethodWorker.run(TestMethodWorker.java:109)at org.testng.TestRunner.privateRun(TestRunner.java:648)at org.testng.TestRunner.run(TestRunner.java:505)at org.testng.SuiteRunner.runTest(SuiteRunner.java:455)at org.testng.SuiteRunner.runSequentially(SuiteRunner.java:450)at org.testng.SuiteRunner.privateRun(SuiteRunner.java:415)at org.testng.SuiteRunner.run(SuiteRunner.java:364)at org.testng.SuiteRunnerWorker.runSuite(SuiteRunnerWorker.java:52)at org.testng.SuiteRunnerWorker.run(SuiteRunnerWorker.java:84)at org.testng.TestNG.runSuitesSequentially(TestNG.java:1187)at org.testng.TestNG.runSuitesLocally(TestNG.java:1116)at org.testng.TestNG.runSuites(TestNG.java:1028)at org.testng.TestNG.run(TestNG.java:996)at org.testng.remote.AbstractRemoteTestNG.run(AbstractRemoteTestNG.java:114)at org.testng.remote.RemoteTestNG.initAndRun(RemoteTestNG.java:251)at org.testng.remote.RemoteTestNG.main(RemoteTestNG.java:77)]]>
    </failure>
  </testcase> <!-- test1 -->
  <testcase name="test" time="0.016" classname="com.ajay.java.TestNG.AssertionInTestNG"/>
  <testcase name="test3" time="0.004" classname="com.ajay.java.TestNG.AssertionInTestNG"/>
</testsuite> <!-- com.ajay.java.TestNG.AssertionInTestNG -->
